Workbook

Sheet 01 · Summary
A1: THE TALENT PREMIUM — L2
A2: Revenue Fluent · Five Verdict Areas · Forward Projection · Board Statement
B3: ORGANISATION INPUTS
B4: Organisation name | C4: [Enter your org name]
B5: Total employees | C5: [Enter number] | D5: Number of people in org
B6: Geography / Currency | C6: [e.g. USD · New York] | D6: Determines currency display
B7: Total compensation base | C7: [Enter annual salary bill] | D7: $#,##0
B8: Assessment period | C8: [e.g. FY2026 · Q1] | D8: Period this model covers
B9: HR function cost | C9: [Annual HR team + tools cost] | D9: $#,##0
B11: TALENT QUALITY PREMIUM (TQP)
B12: Talent Quality Premium | C12: [Enter TQP from platform]
B13: HCI Coefficient | C13: [0.70 – 1.30] | D13: Human Confidence Index
B14: HCI-Adjusted TQP | C14: =IFERROR(C12*C13,"") | D14: Base TQP x HCI coefficient
B16: TQP COMPONENTS
B17: Component | C17: Value | D17: % of TQP | E17: Notes
B18: Performance Premium | C18: [Enter from platform] | D18: =IFERROR(C18/C12,"-") | E18: Staff above grade performance baseline
B19: Retention Premium | C19: [Enter from platform] | D19: =IFERROR(C19/C12,"-") | E19: Stars / HPs / HiPos retained above baseline
B20: Hiring Premium | C20: [Enter from platform] | D20: =IFERROR(C20/C12,"-") | E20: Recent hires (< 1yr) above baseline
B21: TOTAL TQP | C21: =SUM(C18:C20) | D21: =IFERROR(C21/C12,"-") | E21: Sum of three components
B23: BENCHMARK POSITION
B24: Benchmark | C24: TQP Value | D24: vs Your Org | E24: Source
B25: Market average (all scenarios) | C25: [Enter from platform] | E25: Revenue Fluent dataset · 15 scenarios
B26: Your organisation | C26: =C12 | E26: Computed from your inputs
B27: Variance (vs market) | C27: =IFERROR(C26-C25,"") | E27: Positive = above market
B29: FIVE VERDICT AREAS — SUMMARY
B30: Verdict Area | C30: Score /100 | D30: Signal | E30: vs Market Avg
B31: Promotion Accuracy | C31: [Enter from platform] | D31: =IF(C31="[Enter from platform]","",IF(C31>=70,"Strong",IF(C31>=50,"Watch","Weak"))) | E31: =IF(C31="[Enter from platform]","",C31-85)
B32: Manager Quality | C32: [Enter from platform] | D32: =IF(C32="[Enter from platform]","",IF(C32>=70,"Strong",IF(C32>=50,"Watch","Weak"))) | E32: =IF(C32="[Enter from platform]","",C32-62)
B33: Hiring Quality | C33: [Enter from platform] | D33: =IF(C33="[Enter from platform]","",IF(C33>=70,"Strong",IF(C33>=50,"Watch","Weak"))) | E33: =IF(C33="[Enter from platform]","",C33-46)
B34: Selective Retention | C34: [Enter from platform] | D34: =IF(C34="[Enter from platform]","",IF(C34>=70,"Strong",IF(C34>=50,"Watch","Weak"))) | E34: =IF(C34="[Enter from platform]","",C34-59)
B35: HiPo Identification | C35: [Enter from platform] | D35: =IF(C35="[Enter from platform]","",IF(C35>=70,"Strong",IF(C35>=50,"Watch","Weak"))) | E35: =IF(C35="[Enter from platform]","",C35-40)
B36: Overall Verdict Score | C36: =IFERROR(AVERAGE(C31,C32,C33,C34,C35),"") | D36: =IF(C36="","",IF(C36>=70,"Strong",IF(C36>=50,"Watch","Weak")))
B38: HOW TO USE: Enter values in LAVENDER cells. All grey cells are auto-calculated. Copy scores from the Revenue Fluent platform.

Sheet 02 · Five Verdicts
A1: FIVE VERDICT AREAS
A2: Promotion Accuracy · Manager Quality · Hiring Quality · Selective Retention · HiPo Identification
B4: V1 — Promotion Accuracy
B5: Are promotions landing on the right people? Measures Stars above grade performance midpoint.
B6: Input | C6: Your Value | D6: Market Avg Score | E6: Notes
B7: Total Stars | C7: [Enter number] | E7: Star-rated employees in org
B8: Stars at/above grade midpoint | C8: [Enter number] | E8: Stars performing above grade average
B9: Promotion Accuracy Score | C9: [Enter from platform] | D9: 85 | E9: =Stars above midpoint / Total Stars x 100
B10: Signal | C10: =IF(C9="[Enter from platform]","",IF(C9>=70,"STRONG",IF(C9>=50,"WATCH","WEAK"))) | D10: =IF(C9="[Enter from platform]","",C9-85) | E10: vs market average
B11: Grade mismatches | C11: [Enter number] | E11: Stars below grade performance midpoint
B12: C-Suite Inconsistent | C12: [Enter number] | E12: Senior leaders rated Inconsistent
B13: Key Finding | C13: [Paste finding from platform or write your own]
B15: V2 — Manager Quality
B16: Are managers outperforming their direct report average? The only test of management quality that matters financially.
B17: Input | C17: Your Value | D17: Market Avg Score | E17: Notes
B18: Total managers | C18: [Enter number] | E18: People managers in org
B19: Managers below team avg | C19: [Enter number] | E19: Managers performing below their direct reports
B20: Manager Quality Score | C20: [Enter from platform] | D20: 62 | E20: =(Managers - Below avg) / Total managers x 100
B21: Signal | C21: =IF(C20="[Enter from platform]","",IF(C20>=70,"STRONG",IF(C20>=50,"WATCH","WEAK"))) | D21: =IF(C20="[Enter from platform]","",C20-62) | E21: vs market average
B22: Star-to-manager ratio | C22: [Enter x.x] | E22: Stars per manager — higher = stronger pipeline
B23: Teams with no Star manager | C23: [Enter number] | E23: Teams where manager is below team average
B24: Key Finding | C24: [Paste finding from platform or write your own]
B26: V3 — Hiring Quality
B27: Are recent hires (tenure < 1yr) outperforming their grade baseline? Your intake bar determines 3yr talent trajectory.
B28: Input | C28: Your Value | D28: Market Avg Score | E28: Notes
B29: Total recent hires (<1yr) | C29: [Enter number] | E29: Employees hired in last 12 months
B30: Recent hires above baseline | C30: [Enter number] | E30: New hires outperforming grade average
B31: Hiring Quality Score | C31: [Enter from platform] | D31: 46 | E31: =Hires above baseline / Total recent hires x 100
B32: Signal | C32: =IF(C31="[Enter from platform]","",IF(C31>=70,"STRONG",IF(C31>=50,"WATCH","WEAK"))) | D32: =IF(C31="[Enter from platform]","",C31-46) | E32: vs market average
B33: Early Inconsistent Performers | C33: [Enter number] | E33: New hires already rated Inconsistent
B34: Avg ramp time to baseline | C34: [Enter months] | E34: Months to reach grade performance average
B35: Key Finding | C35: [Paste finding from platform or write your own]
B37: V4 — Selective Retention
B38: Not how many left — but who left. Stars staying longer than Inconsistent Performers is the signal.
B39: Input | C39: Your Value | D39: Market Avg Score | E39: Notes
B40: Star avg tenure (years) | C40: [Enter x.x] | E40: Average tenure of Star-rated employees
B41: Inconsistent avg tenure (years) | C41: [Enter x.x] | E41: Average tenure of Inconsistent Performers
B42: Selective Retention Score | C42: [Enter from platform] | D42: 59 | E42: Star tenure vs Inconsistent tenure differential — normalised
B43: Signal | C43: =IF(C42="[Enter from platform]","",IF(C42>=70,"STRONG",IF(C42>=50,"WATCH","WEAK"))) | D43: =IF(C42="[Enter from platform]","",C42-59) | E43: vs market average
B44: Total Inconsistent Performers | C44: [Enter number] | E44: Current Inconsistent Performers in org
...

Sheet 03 · Forward Projection
A1: FORWARD PROJECTION
A2: Scenario model · Conservative / Your Assessment / Optimistic · Lever uplift modelling
B3: BASE TQP (from Summary tab)
B4: Base TQP (HCI-adjusted) | C4: =IFERROR('01 · Summary'!C14,"") | E4: Pulled from Summary tab
B6: IMPROVEMENT LEVERS
B7: Lever | C7: Verdict Area | D7: Estimated Uplift | E7: Include? (Y/N)
B8: Upgrade manager layer | C8: Manager Quality | D8: =IFERROR('01 · Summary'!C14*0.12,"") | E8: Y
B9: Raise hiring bar | C9: Hiring Quality | D9: =IFERROR('01 · Summary'!C14*0.08,"") | E9: Y
B10: Activate HiPo pipeline | C10: HiPo Identification | D10: =IFERROR('01 · Summary'!C14*0.06,"") | E10: Y
B11: Tighten promotion criteria | C11: Promotion Accuracy | D11: =IFERROR('01 · Summary'!C14*0.05,"") | E11: N
B12: Invert retention focus | C12: Selective Retention | D12: =IFERROR('01 · Summary'!C14*0.07,"") | E12: N
B14: SELECTED LEVER UPLIFT
B15: Total selected uplift | C15: =IFERROR(IF(E8="Y",D8,0)+IF(E9="Y",D9,0)+IF(E10="Y",D10,0)+IF(E11="Y",D11,0)+IF(E12="Y",D12,0),"")
B17: THREE-SCENARIO PROJECTION
B18: Line Item | C18: Conservative | D18: Your Assessment | E18: Optimistic
B19: Current TQP (base) | C19: =IFERROR('01 · Summary'!C14*0.85,"") | D19: =IFERROR('01 · Summary'!C14,"") | E19: =IFERROR('01 · Summary'!C14*1.15,"")
B20: Lever uplift (selected) | C20: =IFERROR(C15*0.85,"") | D20: =IFERROR(C15,"") | E20: =IFERROR(C15*1.15,"")
B22: PROJECTED TQP | C22: =IFERROR(C19+C20,"") | D22: =IFERROR(D19+D20,"") | E22: =IFERROR(E19+E20,"")
B23: vs Current TQP | C23: =IFERROR(C22-'01 · Summary'!C14,"") | D23: =IFERROR(D22-'01 · Summary'!C14,"") | E23: =IFERROR(E22-'01 · Summary'!C14,"")
B24: Uplift % | C24: =IFERROR(IFERROR(C22/ABS('01 · Summary'!C14),0),"") | D24: =IFERROR(IFERROR(D22/ABS('01 · Summary'!C14),0),"") | E24: =IFERROR(IFERROR(E22/ABS('01 · Summary'!C14),0),"")
B26: NOTE: This is a scenario model, not a forecast. Conservative = -15% conditions; Optimistic = +15% conditions.

Sheet 04 · HCI & Workings
A1: HUMAN CONFIDENCE INDEX & SHOW WORKINGS
A2: HCI coefficient · Four observable factors · Three-scenario analysis · TQP methodology
B3: THE HUMAN CONFIDENCE INDEX (HCI)
B4: The HCI is a named coefficient (0.70 to 1.30) that adjusts the raw TQP for organisational conditions. Four observable factors. Each YES adds +0.15 to the base of 0.70.
B5: HCI Factor | C5: Yes / No | D5: Impact | E5: Guidance
B6: Leadership Stability | C6: YES | D6: +0.15 | E6: Is leadership stable, present, and actively engaged right now?
B7: Org Disruption Free | C7: YES | D7: +0.15 | E7: Is the org free from major disruption, restructure, M&A, or crisis?
B8: Culture Health | C8: YES | D8: +0.15 | E8: Is the culture broadly functional and not in crisis?
B9: Execution Momentum | C9: YES | D9: +0.15 | E9: Is the org executing well against its current strategic priorities?
B10: HCI Coefficient | C10: =0.7+(IF(C6="YES",1,0)+IF(C7="YES",1,0)+IF(C8="YES",1,0)+IF(C9="YES",1,0))*0.15 | D10: 0.70 + (count of YES x 0.15)
B12: THREE HCI SCENARIOS
B13: Scenario | C13: HCI | D13: Adjusted TQP | E13: Interpretation
B14: Conservative | C14: =MAX(0.7,C10-0.15) | D14: =IFERROR(C14*'01 · Summary'!C12,"") | E14: HCI -0.15 — conditions slightly worse than assessed
B15: Your Assessment | C15: =C10 | D15: =IFERROR(C15*'01 · Summary'!C12,"") | E15: Your HCI — the number you should present
B16: Optimistic | C16: =MIN(1.3,C10+0.15) | D16: =IFERROR(C16*'01 · Summary'!C12,"") | E16: HCI +0.15 — conditions slightly better than assessed
B18: SHOW WORKINGS — TQP METHODOLOGY
B19: PERFORMANCE PREMIUM
B20: Formula | C20: Σ (perf_score - grade_avg) × salary for each employee
B21: Input: Grade averages | C21: Computed from all employees in same grade | E21: Revenue Fluent dataset · rf-data.js v5.0
B22: Input: Performance surplus | C22: Per-employee deviation above/below grade benchmark | E22: Salary-weighted
B23: Output | C23: Total financial value of above-baseline performance | E23: $#,##0
B25: RETENTION PREMIUM
B26: Formula | C26: (surplus × salary × 0.5) + (replace cost × 0.1) for Stars, HPs, HiPos
B27: Replace cost assumption | C27: 1.5× annual salary (industry standard) | E27: Source: SHRM / Deloitte HR benchmarks
B28: Eligible employees | C28: Stars, High Performers, High Potentials above grade baseline
B29: Output | C29: Value of above-baseline keepers + avoided replacement cost | E29: $#,##0
B31: HIRING PREMIUM
B32: Formula | C32: (perf_surplus × salary) for recent hires above grade baseline
B33: Recent hire definition | C33: Tenure ≤ 1 year at time of assessment
B34: Output | C34: Incremental value of above-baseline new hires | E34: $#,##0
B36: TQP = Performance Premium + Retention Premium + Hiring Premium
B37: HCI-Adjusted TQP = TQP × HCI Coefficient

Sheet 05 · Board Statement
A1: BOARD-READY INTELLIGENCE STATEMENT
A2: Copy this statement into your board pack, CEO presentation, or HR committee report.
B3: TALENT QUALITY PREMIUM
B4: [Organisation name] generated a Talent Quality Premium of [TQP value] in [period] — the financial value of having better-than-average people at the same compensation cost. HCI-adjusted TQP: [HCI-Adjusted TQP]. HCI coefficient: [HCI].
B6: FIVE VERDICT AREAS
B7: Promotion Accuracy scored [score]/100 ([Strong/Watch/Weak] vs market average of 85). [1-line key finding]
B8: Manager Quality scored [score]/100 ([Strong/Watch/Weak] vs market average of 62). [1-line key finding]
B9: Hiring Quality scored [score]/100 ([Strong/Watch/Weak] vs market average of 46). [1-line key finding]
B10: Selective Retention scored [score]/100 ([Strong/Watch/Weak] vs market average of 59). [1-line key finding]
B11: HiPo Identification scored [score]/100 ([Strong/Watch/Weak] vs market average of 40). [1-line key finding]
B13: FORWARD PROJECTION
B14: Addressing the [Watch/Weak] verdict areas through [lever names] is projected to generate a TQP uplift of [projected uplift] under the conservative scenario and [optimistic uplift] under the optimistic scenario.
B16: HUMACITY POSITION
B17: [Organisation name]'s Humacity position is [improving / stable / declining]. The primary driver is [one sentence]. The recommended priority intervention is [intervention name].
... B22: INSTRUCTIONS: Replace all [bracketed text] with your actual figures from the Summary and Five Verdicts tabs. This statement is board-ready as-is once values are filled in.
